Workbook

Sheet Summary
A1: Test Summary
A2: Sauce Demo - Shop and check out - results recorded 27-28 Oct 2026 in Chrome, Firefox and Safari (WebKit)
A4: Suite | B4: Test Cases | C4: Pass | D4: Fail | E4: Not Run
A5: Core Test Cases (A1) | B5: =COUNTA('Core Test Cases (A1)'!$A$6:$A$30) -> 25 | C5: =COUNTIF('Core Test Cases (A1)'!$L$6:$L$30,"Pass") -> 24 | D5: =COUNTIF('Core Test Cases (A1)'!$L$6:$L$30,"Fail") -> 1 | E5: =COUNTIF('Core Test Cases (A1)'!$L$6:$L$30,"Not Run") -> 0
A6: Extended Test Cases | B6: =COUNTA('Extended Test Cases'!$A$6:$A$78) -> 73 | C6: =COUNTIF('Extended Test Cases'!$L$6:$L$78,"Pass") -> 63 | D6: =COUNTIF('Extended Test Cases'!$L$6:$L$78,"Fail") -> 10 | E6: =COUNTIF('Extended Test Cases'!$L$6:$L$78,"Not Run") -> 0
A7: Total | B7: =B5+B6 -> 98 | C7: =C5+C6 -> 87 | D7: =D5+D6 -> 11 | E7: =E5+E6 -> 0
A8: Bugs found | B8: =COUNTA(Bugs!$A$5:$A$15) -> 11
A10: Area | B10: Test Cases | C10: Pass | D10: Fail | E10: Not Run
A11: Login | B11: =COUNTIF('Core Test Cases (A1)'!$B$6:$B$30,$A11)+COUNTIF('Extended Test Cases'!$B$6:$B$78,$A11) -> 19 | C11: =COUNTIFS('Core Test Cases (A1)'!$B$6:$B$30,$A11,'Core Test Cases (A1)'!$L$6:$L$30,"Pass")+COUNTIFS('Extended Test Cases'!$B$6:$B$78,$A11,'Extended Test Cases'!$L$6:$L$78,"Pass") -> 19 | D11: =COUNTIFS('Core Test Cases (A1)'!$B$6:$B$30,$A11,'Core Test Cases (A1)'!$L$6:$L$30,"Fail")+COUNTIFS('Extended Test Cases'!$B$6:$B$78,$A11,'Extended Test Cases'!$L$6:$L$78,"Fail") -> 0 | E11: =COUNTIFS('Core Test Cases (A1)'!$B$6:$B$30,$A11,'Core Test Cases (A1)'!$L$6:$L$30,"Not Run")+COUNTIFS('Extended Test Cases'!$B$6:$B$78,$A11,'Extended Test Cases'!$L$6:$L$78,"Not Run") -> 0
A12: Products | B12: =COUNTIF('Core Test Cases (A1)'!$B$6:$B$30,$A12)+COUNTIF('Extended Test Cases'!$B$6:$B$78,$A12) -> 6 | C12: =COUNTIFS('Core Test Cases (A1)'!$B$6:$B$30,$A12,'Core Test Cases (A1)'!$L$6:$L$30,"Pass")+COUNTIFS('Extended Test Cases'!$B$6:$B$78,$A12,'Extended Test Cases'!$L$6:$L$78,"Pass") -> 6 | D12: =COUNTIFS('Core Test Cases (A1)'!$B$6:$B$30,$A12,'Core Test Cases (A1)'!$L$6:$L$30,"Fail")+COUNTIFS('Extended Test Cases'!$B$6:$B$78,$A12,'Extended Test Cases'!$L$6:$L$78,"Fail") -> 0 | E12: =COUNTIFS('Core Test Cases (A1)'!$B$6:$B$30,$A12,'Core Test Cases (A1)'!$L$6:$L$30,"Not Run")+COUNTIFS('Extended Test Cases'!$B$6:$B$78,$A12,'Extended Test Cases'!$L$6:$L$78,"Not Run") -> 0
A13: Sorting | B13: =COUNTIF('Core Test Cases (A1)'!$B$6:$B$30,$A13)+COUNTIF('Extended Test Cases'!$B$6:$B$78,$A13) -> 7 | C13: =COUNTIFS('Core Test Cases (A1)'!$B$6:$B$30,$A13,'Core Test Cases (A1)'!$L$6:$L$30,"Pass")+COUNTIFS('Extended Test Cases'!$B$6:$B$78,$A13,'Extended Test Cases'!$L$6:$L$78,"Pass") -> 6 | D13: =COUNTIFS('Core Test Cases (A1)'!$B$6:$B$30,$A13,'Core Test Cases (A1)'!$L$6:$L$30,"Fail")+COUNTIFS('Extended Test Cases'!$B$6:$B$78,$A13,'Extended Test Cases'!$L$6:$L$78,"Fail") -> 1 | E13: =COUNTIFS('Core Test Cases (A1)'!$B$6:$B$30,$A13,'Core Test Cases (A1)'!$L$6:$L$30,"Not Run")+COUNTIFS('Extended Test Cases'!$B$6:$B$78,$A13,'Extended Test Cases'!$L$6:$L$78,"Not Run") -> 0
A14: Product Detail | B14: =COUNTIF('Core Test Cases (A1)'!$B$6:$B$30,$A14)+COUNTIF('Extended Test Cases'!$B$6:$B$78,$A14) -> 5 | C14: =COUNTIFS('Core Test Cases (A1)'!$B$6:$B$30,$A14,'Core Test Cases (A1)'!$L$6:$L$30,"Pass")+COUNTIFS('Extended Test Cases'!$B$6:$B$78,$A14,'Extended Test Cases'!$L$6:$L$78,"Pass") -> 5 | D14: =COUNTIFS('Core Test Cases (A1)'!$B$6:$B$30,$A14,'Core Test Cases (A1)'!$L$6:$L$30,"Fail")+COUNTIFS('Extended Test Cases'!$B$6:$B$78,$A14,'Extended Test Cases'!$L$6:$L$78,"Fail") -> 0 | E14: =COUNTIFS('Core Test Cases (A1)'!$B$6:$B$30,$A14,'Core Test Cases (A1)'!$L$6:$L$30,"Not Run")+COUNTIFS('Extended Test Cases'!$B$6:$B$78,$A14,'Extended Test Cases'!$L$6:$L$78,"Not Run") -> 0
A15: Cart | B15: =COUNTIF('Core Test Cases (A1)'!$B$6:$B$30,$A15)+COUNTIF('Extended Test Cases'!$B$6:$B$78,$A15) -> 12 | C15: =COUNTIFS('Core Test Cases (A1)'!$B$6:$B$30,$A15,'Core Test Cases (A1)'!$L$6:$L$30,"Pass")+COUNTIFS('Extended Test Cases'!$B$6:$B$78,$A15,'Extended Test Cases'!$L$6:$L$78,"Pass") -> 11 | D15: =COUNTIFS('Core Test Cases (A1)'!$B$6:$B$30,$A15,'Core Test Cases (A1)'!$L$6:$L$30,"Fail")+COUNTIFS('Extended Test Cases'!$B$6:$B$78,$A15,'Extended Test Cases'!$L$6:$L$78,"Fail") -> 1 | E15: =COUNTIFS('Core Test Cases (A1)'!$B$6:$B$30,$A15,'Core Test Cases (A1)'!$L$6:$L$30,"Not Run")+COUNTIFS('Extended Test Cases'!$B$6:$B$78,$A15,'Extended Test Cases'!$L$6:$L$78,"Not Run") -> 0
A16: Checkout | B16: =COUNTIF('Core Test Cases (A1)'!$B$6:$B$30,$A16)+COUNTIF('Extended Test Cases'!$B$6:$B$78,$A16) -> 19 | C16: =COUNTIFS('Core Test Cases (A1)'!$B$6:$B$30,$A16,'Core Test Cases (A1)'!$L$6:$L$30,"Pass")+COUNTIFS('Extended Test Cases'!$B$6:$B$78,$A16,'Extended Test Cases'!$L$6:$L$78,"Pass") -> 16 | D16: =COUNTIFS('Core Test Cases (A1)'!$B$6:$B$30,$A16,'Core Test Cases (A1)'!$L$6:$L$30,"Fail")+COUNTIFS('Extended Test Cases'!$B$6:$B$78,$A16,'Extended Test Cases'!$L$6:$L$78,"Fail") -> 3 | E16: =COUNTIFS('Core Test Cases (A1)'!$B$6:$B$30,$A16,'Core Test Cases (A1)'!$L$6:$L$30,"Not Run")+COUNTIFS('Extended Test Cases'!$B$6:$B$78,$A16,'Extended Test Cases'!$L$6:$L$78,"Not Run") -> 0
A17: Order Total | B17: =COUNTIF('Core Test Cases (A1)'!$B$6:$B$30,$A17)+COUNTIF('Extended Test Cases'!$B$6:$B$78,$A17) -> 4 | C17: =COUNTIFS('Core Test Cases (A1)'!$B$6:$B$30,$A17,'Core Test Cases (A1)'!$L$6:$L$30,"Pass")+COUNTIFS('Extended Test Cases'!$B$6:$B$78,$A17,'Extended Test Cases'!$L$6:$L$78,"Pass") -> 4 | D17: =COUNTIFS('Core Test Cases (A1)'!$B$6:$B$30,$A17,'Core Test Cases (A1)'!$L$6:$L$30,"Fail")+COUNTIFS('Extended Test Cases'!$B$6:$B$78,$A17,'Extended Test Cases'!$L$6:$L$78,"Fail") -> 0 | E17: =COUNTIFS('Core Test Cases (A1)'!$B$6:$B$30,$A17,'Core Test Cases (A1)'!$L$6:$L$30,"Not Run")+COUNTIFS('Extended Test Cases'!$B$6:$B$78,$A17,'Extended Test Cases'!$L$6:$L$78,"Not Run") -> 0
A18: Order Completion | B18: =COUNTIF('Core Test Cases (A1)'!$B$6:$B$30,$A18)+COUNTIF('Extended Test Cases'!$B$6:$B$78,$A18) -> 6 | C18: =COUNTIFS('Core Test Cases (A1)'!$B$6:$B$30,$A18,'Core Test Cases (A1)'!$L$6:$L$30,"Pass")+COUNTIFS('Extended Test Cases'!$B$6:$B$78,$A18,'Extended Test Cases'!$L$6:$L$78,"Pass") -> 5 | D18: =COUNTIFS('Core Test Cases (A1)'!$B$6:$B$30,$A18,'Core Test Cases (A1)'!$L$6:$L$30,"Fail")+COUNTIFS('Extended Test Cases'!$B$6:$B$78,$A18,'Extended Test Cases'!$L$6:$L$78,"Fail") -> 1 | E18: =COUNTIFS('Core Test Cases (A1)'!$B$6:$B$30,$A18,'Core Test Cases (A1)'!$L$6:$L$30,"Not Run")+COUNTIFS('Extended Test Cases'!$B$6:$B$78,$A18,'Extended Test Cases'!$L$6:$L$78,"Not Run") -> 0
A19: Navigation | B19: =COUNTIF('Core Test Cases (A1)'!$B$6:$B$30,$A19)+COUNTIF('Extended Test Cases'!$B$6:$B$78,$A19) -> 5 | C19: =COUNTIFS('Core Test Cases (A1)'!$B$6:$B$30,$A19,'Core Test Cases (A1)'!$L$6:$L$30,"Pass")+COUNTIFS('Extended Test Cases'!$B$6:$B$78,$A19,'Extended Test Cases'!$L$6:$L$78,"Pass") -> 4 | D19: =COUNTIFS('Core Test Cases (A1)'!$B$6:$B$30,$A19,'Core Test Cases (A1)'!$L$6:$L$30,"Fail")+COUNTIFS('Extended Test Cases'!$B$6:$B$78,$A19,'Extended Test Cases'!$L$6:$L$78,"Fail") -> 1 | E19: =COUNTIFS('Core Test Cases (A1)'!$B$6:$B$30,$A19,'Core Test Cases (A1)'!$L$6:$L$30,"Not Run")+COUNTIFS('Extended Test Cases'!$B$6:$B$78,$A19,'Extended Test Cases'!$L$6:$L$78,"Not Run") -> 0
A20: Session | B20: =COUNTIF('Core Test Cases (A1)'!$B$6:$B$30,$A20)+COUNTIF('Extended Test Cases'!$B$6:$B$78,$A20) -> 9 | C20: =COUNTIFS('Core Test Cases (A1)'!$B$6:$B$30,$A20,'Core Test Cases (A1)'!$L$6:$L$30,"Pass")+COUNTIFS('Extended Test Cases'!$B$6:$B$78,$A20,'Extended Test Cases'!$L$6:$L$78,"Pass") -> 9 | D20: =COUNTIFS('Core Test Cases (A1)'!$B$6:$B$30,$A20,'Core Test Cases (A1)'!$L$6:$L$30,"Fail")+COUNTIFS('Extended Test Cases'!$B$6:$B$78,$A20,'Extended Test Cases'!$L$6:$L$78,"Fail") -> 0 | E20: =COUNTIFS('Core Test Cases (A1)'!$B$6:$B$30,$A20,'Core Test Cases (A1)'!$L$6:$L$30,"Not Run")+COUNTIFS('Extended Test Cases'!$B$6:$B$78,$A20,'Extended Test Cases'!$L$6:$L$78,"Not Run") -> 0
A21: Accessibility | B21: =COUNTIF('Core Test Cases (A1)'!$B$6:$B$30,$A21)+COUNTIF('Extended Test Cases'!$B$6:$B$78,$A21) -> 1 | C21: =COUNTIFS('Core Test Cases (A1)'!$B$6:$B$30,$A21,'Core Test Cases (A1)'!$L$6:$L$30,"Pass")+COUNTIFS('Extended Test Cases'!$B$6:$B$78,$A21,'Extended Test Cases'!$L$6:$L$78,"Pass") -> 1 | D21: =COUNTIFS('Core Test Cases (A1)'!$B$6:$B$30,$A21,'Core Test Cases (A1)'!$L$6:$L$30,"Fail")+COUNTIFS('Extended Test Cases'!$B$6:$B$78,$A21,'Extended Test Cases'!$L$6:$L$78,"Fail") -> 0 | E21: =COUNTIFS('Core Test Cases (A1)'!$B$6:$B$30,$A21,'Core Test Cases (A1)'!$L$6:$L$30,"Not Run")+COUNTIFS('Extended Test Cases'!$B$6:$B$78,$A21,'Extended Test Cases'!$L$6:$L$78,"Not Run") -> 0
A22: Screen size | B22: =COUNTIF('Core Test Cases (A1)'!$B$6:$B$30,$A22)+COUNTIF('Extended Test Cases'!$B$6:$B$78,$A22) -> 1 | C22: =COUNTIFS('Core Test Cases (A1)'!$B$6:$B$30,$A22,'Core Test Cases (A1)'!$L$6:$L$30,"Pass")+COUNTIFS('Extended Test Cases'!$B$6:$B$78,$A22,'Extended Test Cases'!$L$6:$L$78,"Pass") -> 1 | D22: =COUNTIFS('Core Test Cases (A1)'!$B$6:$B$30,$A22,'Core Test Cases (A1)'!$L$6:$L$30,"Fail")+COUNTIFS('Extended Test Cases'!$B$6:$B$78,$A22,'Extended Test Cases'!$L$6:$L$78,"Fail") -> 0 | E22: =COUNTIFS('Core Test Cases (A1)'!$B$6:$B$30,$A22,'Core Test Cases (A1)'!$L$6:$L$30,"Not Run")+COUNTIFS('Extended Test Cases'!$B$6:$B$78,$A22,'Extended Test Cases'!$L$6:$L$78,"Not Run") -> 0
A23: Personas | B23: =COUNTIF('Core Test Cases (A1)'!$B$6:$B$30,$A23)+COUNTIF('Extended Test Cases'!$B$6:$B$78,$A23) -> 4 | C23: =COUNTIFS('Core Test Cases (A1)'!$B$6:$B$30,$A23,'Core Test Cases (A1)'!$L$6:$L$30,"Pass")+COUNTIFS('Extended Test Cases'!$B$6:$B$78,$A23,'Extended Test Cases'!$L$6:$L$78,"Pass") -> 0 | D23: =COUNTIFS('Core Test Cases (A1)'!$B$6:$B$30,$A23,'Core Test Cases (A1)'!$L$6:$L$30,"Fail")+COUNTIFS('Extended Test Cases'!$B$6:$B$78,$A23,'Extended Test Cases'!$L$6:$L$78,"Fail") -> 4 | E23: =COUNTIFS('Core Test Cases (A1)'!$B$6:$B$30,$A23,'Core Test Cases (A1)'!$L$6:$L$30,"Not Run")+COUNTIFS('Extended Test Cases'!$B$6:$B$78,$A23,'Extended Test Cases'!$L$6:$L$78,"Not Run") -> 0
A24: Total | B24: =SUM(B11:B23) -> 98 | C24: =SUM(C11:C23) -> 87 | D24: =SUM(D11:D23) -> 11 | E24: =SUM(E11:E23) -> 0

Sheet Core Test Cases (A1)
A1: Core Test Cases - Section A1 (25 cases)
A2: Use case: Shop and check out. These 25 cases cover every business rule in the brief.
A3: Website: https://www.saucedemo.com | Password for all users: secret_sauce | Results recorded 27-28 Oct 2026 in Chrome, Firefox and Safari (WebKit). Pass = worked in all three browsers. Bug ID "N/A" = no bug found.
A5: ID | B5: Area | C5: Type | D5: Title | E5: Pre-conditions | F5: Steps | G5: Test data | H5: Expected result | I5: Priority (P1-P3) | J5: Automate? (Yes / No) and why | K5: Actual Result | L5: Status | M5: Bug ID | N5: Remarks
A6: TC01 | B6: Login | C6: Positive | D6: Login with a valid user | E6: Use a NEW private / incognito browser window (so the cart is empty and no one is logged in). | F6: 1. Open https://www.saucedemo.com 2. Enter "standard_user" in Username and "secret_sauce" in Password 3. Click Login 4. Look at the page | G6: Username: standard_user Password: secret_sauce | H6: 1. Login page shows the Username field, Password field and Login button. 2. Text is typed. Password shows as dots. 3. Products page opens. URL ends with /inventory.html. Title is "Products". Products are listed. No cart number on the cart icon. 4. Menu button (☰) is visible. No error message is shown. | I6: P1 | J6: Yes - smoke test for every build; every journey starts with login. | K6: As expected - Menu button (☰) is visible. No error message is shown. | L6: Pass | M6: N/A
A7: TC02 | B7: Login | C7: Negative | D7: Login with a locked user | E7: Use a NEW private / incognito browser window (so the cart is empty and no one is logged in). | F7: 1. Open https://www.saucedemo.com 2. Enter "locked_out_user" and "secret_sauce" 3. Click Login 4. Look at the page and the URL | G7: Username: locked_out_user Password: secret_sauce | H7: 1. Login page is shown. 2. Text is typed. 3. Error shown: "Epic sadface: Sorry, this user has been locked out." 4. Still on the login page (Username, Password, Login visible). URL does NOT contain /inventory.html. "Products" title is NOT shown. | I7: P1 | J7: Yes - access-control rule with an exact error message. | K7: As expected - error "Epic sadface: Sorry, this user has been locked out." was shown and the user stayed on the login page. | L7: Pass | M7: N/A
A8: TC03 | B8: Login | C8: Negative | D8: Login with a wrong password | E8: Use a NEW private / incognito browser window (so the cart is empty and no one is logged in). | F8: 1. Open https://www.saucedemo.com 2. Enter "standard_user" and "not_the_demo_password" 3. Click Login 4. Look at the page and the URL | G8: Username: standard_user Password: not_the_demo_password | H8: 1. Login page is shown. 2. Text is typed. 3. Error shown: "Epic sadface: Username and password do not match any user in this service" 4. Still on the login page. URL does NOT contain /inventory.html. "Products" title is NOT shown. | I8: P1 | J8: Yes - access-control rule; cheap and stable. | K8: As expected - error "Epic sadface: Username and password do not match any user in this service" was shown and the user stayed on the login page. | L8: Pass | M8: N/A
A9: TC04 | B9: Login | C9: Negative / Boundary | D9: Login with both fields empty | E9: Use a NEW private / incognito browser window (so the cart is empty and no one is logged in). | F9: 1. Open https://www.saucedemo.com 2. Leave Username and Password empty 3. Click Login 4. Look at the page and the URL | G9: Username: (empty) Password: (empty) | H9: 1. Login page is shown. 2. Both fields are empty. 3. Error shown: "Epic sadface: Username is required" 4. Still on the login page. URL does NOT contain /inventory.html. | I9: P2 | J9: Yes - required-field rule; fast and stable. | K9: As expected - error "Epic sadface: Username is required" was shown and the user stayed on the login page. | L9: Pass | M9: N/A
A10: TC05 | B10: Sorting | C10: Positive | D10: Sort by "Name (A to Z)" | E10: Use a NEW private / incognito browser window (so the cart is empty and no one is logged in). | F10: 1. Open https://www.saucedemo.com 2. Enter "standard_user" in Username and "secret_sauce" in Password 3. Click Login 4. Write down every product name and price 5. In the sort dropdown, select "Name (Z to A)" 6. Select "Name (A to Z)" 7. Read every product name from top to bottom 8. Compare the list with the one you wrote down 9. Look at the sort dropdown | G10: User: standard_user 6 products (two cost $15.99) | H10: 1. Login page shows the Username field, Password field and Login button. 2. Text is typed. Password shows as dots. 3. Products page opens. URL ends with /inventory.html. Title is "Products". Products are listed. No cart number on the cart icon. 4. 6 products are listed. 5. The list re-orders. 6. The list re-orders. 7. Every name comes before (or equals) the next one, A to Z. 8. Same 6 products with the same prices. Nothing missing, added or re-priced. 9. It shows "Name (A to Z)". | I10: P2 | J10: Yes - checking every product in order is slow and error-prone by hand. | K10: As expected - all 6 names were in A to Z order, nothing was missing, and the dropdown showed "Name (A to Z)". | L10: Pass | M10: N/A
A11: TC06 | B11: Sorting | C11: Positive | D11: Sort by "Name (Z to A)" | E11: Use a NEW private / incognito browser window (so the cart is empty and no one is logged in). | F11: 1. Open https://www.saucedemo.com 2. Enter "standard_user" in Username and "secret_sauce" in Password 3. Click Login 4. Write down every product name and price 5. In the sort dropdown, select "Name (A to Z)" 6. Select "Name (Z to A)" 7. Read every product name from top to bottom 8. Compare the list with the one you wrote down 9. Look at the sort dropdown | G11: User: standard_user 6 products (two cost $15.99) | H11: 1. Login page shows the Username field, Password field and Login button. 2. Text is typed. Password shows as dots. 3. Products page opens. URL ends with /inventory.html. Title is "Products". Products are listed. No cart number on the cart icon. 4. 6 products are listed. 5. The list re-orders. 6. The list re-orders. 7. Every name comes after (or equals) the next one, Z to A. 8. Same 6 products with the same prices. Nothing missing, added or re-priced. 9. It shows "Name (Z to A)". | I11: P2 | J11: Yes - whole-list check, easy to repeat on every build. | K11: As expected - all 6 names were in Z to A order, nothing was missing, and the dropdown showed "Name (Z to A)". | L11: Pass | M11: N/A
A12: TC07 | B12: Sorting | C12: Positive | D12: Sort by "Price (low to high)" | E12: Use a NEW private / incognito browser window (so the cart is empty and no one is logged in). | F12: 1. Open https://www.saucedemo.com 2. Enter "standard_user" in Username and "secret_sauce" in Password 3. Click Login 4. Write down every product name and price 5. In the sort dropdown, select "Price (high to low)" 6. Select "Price (low to high)" 7. Read every price from top to bottom 8. Compare the list with the one you wrote down 9. Look at the sort dropdown | G12: User: standard_user 6 products (two cost $15.99) | H12: 1. Login page shows the Username field, Password field and Login button. 2. Text is typed. Password shows as dots. 3. Products page opens. URL ends with /inventory.html. Title is "Products". Products are listed. No cart number on the cart icon. 4. 6 products are listed. 5. The list re-orders. 6. The list re-orders. 7. Every price is lower than or equal to the next: $7.99, $9.99, $15.99, $15.99, $29.99, $49.99 (the two $15.99 items can be in either order). 8. Same 6 products with the same prices. Nothing missing, added or re-priced. 9. It shows "Price (low to high)". | I12: P1 | J12: Yes - whole-list check; this is the B3 regression. | K12: As expected - prices were $7.99, $9.99, $15.99, $15.99, $29.99, $49.99. | L12: Pass | M12: N/A
A13: TC08 | B13: Sorting | C13: Positive | D13: Sort by "Price (high to low)" | E13: Use a NEW private / incognito browser window (so the cart is empty and no one is logged in). | F13: 1. Open https://www.saucedemo.com 2. Enter "standard_user" in Username and "secret_sauce" in Password 3. Click Login 4. Write down every product name and price 5. In the sort dropdown, select "Price (low to high)" 6. Select "Price (high to low)" 7. Read every price from top to bottom 8. Compare the list with the one you wrote down 9. Look at the sort dropdown | G13: User: standard_user 6 products (two cost $15.99) | H13: 1. Login page shows the Username field, Password field and Login button. 2. Text is typed. Password shows as dots. 3. Products page opens. URL ends with /inventory.html. Title is "Products". Products are listed. No cart number on the cart icon. 4. 6 products are listed. 5. The list re-orders. 6. The list re-orders. 7. Every price is higher than or equal to the next: $49.99, $29.99, $15.99, $15.99, $9.99, $7.99. 8. Same 6 products with the same prices. Nothing missing, added or re-priced. 9. It shows "Price (high to low)". | I13: P2 | J13: Yes - whole-list check, easy to repeat on every build. | K13: As expected - prices were $49.99, $29.99, $15.99, $15.99, $9.99, $7.99. | L13: Pass | M13: N/A
A14: TC09 | B14: Cart | C14: Positive | D14: Add two products and remove one from the Products page | E14: Use a NEW private / incognito browser window (so the cart is empty and no one is logged in). | F14: 1. Open https://www.saucedemo.com 2. Enter "standard_user" in Username and "secret_sauce" in Password 3. Click Login 4. Note the prices of Sauce Labs Backpack and Sauce Labs Bike Light 5. Click "Add to cart" on Backpack, then on Bike Light 6. Look at the cart icon 7. On the Products page, click "Remove" on Backpack 8. Look at the cart icon 9. Click the cart icon 10. Check the items in the cart | G14: User: standard_user Products: Sauce Labs Backpack ($29.99), Sauce Labs Bike Light ($9.99) | H14: 1. Login page shows the Username field, Password field and Login button. 2. Text is typed. Password shows as dots. 3. Products page opens. URL ends with /inventory.html. Title is "Products". Products are listed. No cart number on the cart icon. 4. Backpack $29.99, Bike Light $9.99. 5. Both buttons change to "Remove". 6. Cart number shows 2. 7. Backpack button changes back to "Add to cart". 8. Cart number shows 1. 9. "Your Cart" page opens. URL ends with /cart.html. 10. Only Sauce Labs Bike Light is in the cart, price $9.99 (same as Products page). | I14: P1 | J14: Yes - core cart rule (badge and contents). | K14: As expected - Only Sauce Labs Bike Light is in the cart, price $9.99 (same as Products page). | L14: Pass | M14: N/A
A15: TC10 | B15: Cart | C15: Positive | D15: Remove products on the Cart page | E15: Use a NEW private / incognito browser window (so the cart is empty and no one is logged in). | F15: 1. Open https://www.saucedemo.com 2. Enter "standard_user" in Username and "secret_sauce" in Password 3. Click Login 4. Click "Add to cart" on Bolt T-Shirt and on Onesie 5. Click the cart icon 6. Check the items in the cart 7. Click "Remove" on Bolt T-Shirt 8. Click "Remove" on Onesie | G15: User: standard_user Products: Sauce Labs Bolt T-Shirt ($15.99), Sauce Labs Onesie ($7.99) | H15: 1. Login page shows the Username field, Password field and Login button. 2. Text is typed. Password shows as dots. 3. Products page opens. URL ends with /inventory.html. Title is "Products". Products are listed. No cart number on the cart icon. 4. Both buttons change to "Remove". 5. "Your Cart" page opens. 6. Exactly 2 items: Bolt T-Shirt $15.99 and Onesie $7.99. 7. Bolt T-Shirt disappears. Cart number shows 1. Only Onesie $7.99 is left. 8. Onesie disappears. Cart number is gone. Cart list is empty. | I15: P1 | J15: Yes - core cart rule. | K15: As expected - Onesie disappears. Cart number is gone. Cart list is empty. | L15: Pass | M15: N/A
A16: TC11 | B16: Cart | C16: Positive | D16: New session starts with an empty cart | E16: Use a NEW private / incognito browser window (so the cart is empty and no one is logged in). | F16: 1. Open https://www.saucedemo.com 2. Enter "standard_user" in Username and "secret_sauce" in Password 3. Click Login 4. Look at the cart icon and the product buttons 5. Click the cart icon 6. Click "Continue Shopping" | G16: User: standard_user | H16: 1. Login page shows the Username field, Password field and Login button. 2. Text is typed. Password shows as dots. 3. Products page opens. URL ends with /inventory.html. Title is "Products". Products are listed. No cart number on the cart icon. 4. No cart number. No product shows a "Remove" button. 5. "Your Cart" page opens. The cart is empty. 6. Products page opens. No cart number. | I16: P2 | J16: Yes - cheap check of the empty state. | K16: As expected - no cart number, the cart was empty, and "Continue Shopping" went back to Products. | L16: Pass | M16: N/A
A17: TC12 | B17: Checkout | C17: Positive | D17: Place an order with two products | E17: Use a NEW private / incognito browser window (so the cart is empty and no one is logged in). | F17: 1. Open https://www.saucedemo.com 2. Enter "standard_user" in Username and "secret_sauce" in Password 3. Click Login 4. Note the prices, then click "Add to cart" on Backpack and Bolt T-Shirt 5. Click the cart icon 6. Click Checkout 7. Enter Test / Customer / 12345 and click Continue 8. Check the items on the Overview 9. Check Item total, Tax and Total 10. Click Finish 11. Click "Back Home" 12. Click the cart icon | G17: User: standard_user Products: Sauce Labs Backpack ($29.99), Sauce Labs Bolt T-Shirt ($15.99) First Name: Test, Last Name: Customer, Zip: 12345 | H17: 1. Login page shows the Username field, Password field and Login button. 2. Text is typed. Password shows as dots. 3. Products page opens. URL ends with /inventory.html. Title is "Products". Products are listed. No cart number on the cart icon. 4. Both buttons change to "Remove". Cart number shows 2. 5. "Your Cart" page shows exactly Backpack $29.99 and Bolt T-Shirt $15.99. 6. "Checkout: Your Information" page opens. 7. "Checkout: Overview" page opens. URL ends with /checkout-step-two.html. 8. Exactly Backpack $29.99 and Bolt T-Shirt $15.99. 9. Item total = $29.99 + $15.99 = $45.98. Total = Item total + Tax (to the cent). 10. "Checkout: Complete!" page opens. Message: "Thank you for your order!". No cart number. 11. Products page opens. No cart number. No product shows "Remove". 12. The cart is empty. | I17: P1 | J17: Yes - main money journey; totals checked to the cent. | K17: As expected - Item total $45.98 and Total = Item total + Tax. "Thank you for your order!" was shown and the cart was empty afterwards. | L17: Pass | M17: N/A
... A23: TC18 | B23: Order Total | C23: Positive / Boundary | D23: Order total for all six products | E23: Use a NEW private / incognito browser window (so the cart is empty and no one is logged in). | F23: 1. Open https://www.saucedemo.com 2. Enter "standard_user" in Username and "secret_sauce" in Password 3. Click Login 4. Click "Add to cart" on all 6 products 5. Click the cart icon 6. Click Checkout, enter Test / Customer / 12345, click Continue 7. Check the items on the Overview 8. Check Item total, Tax and Total 9. Click Finish 10. Click "Back Home" | G23: User: standard_user Products: all 6 - Backpack $29.99, Bike Light $9.99, Bolt T-Shirt $15.99, Fleece Jacket $49.99, Onesie $7.99, Test.allTheThings() T-Shirt (Red) $15.99 First Name: Test, Last Name: Customer, Zip: 12345 | H23: 1. Login page shows the Username field, Password field and Login button. 2. Text is typed. Password shows as dots. 3. Products page opens. URL ends with /inventory.html. Title is "Products". Products are listed. No cart number on the cart icon. 4. Buttons change to "Remove". Cart number shows 6. 5. "Your Cart" page shows exactly the added products at the Products page prices. 6. "Checkout: Overview" page opens. 7. Exactly the added products at the same prices. 8. Item total = $129.94 (sum of all 6 prices). Total = Item total + Tax (to the cent). 9. Message: "Thank you for your order!" 10. Products page opens. No cart number. | I23: P1 | J23: Yes - largest basket; boundary for the total rule. | K23: As expected - Item total $129.94 and Total = Item total + Tax. Order completed, cart empty. | L23: Pass | M23: N/A
A24: TC19 | B24: Order Completion | C24: Negative | D24: Double-click Finish | E24: Use a NEW private / incognito browser window (so the cart is empty and no one is logged in). | F24: 1. Open https://www.saucedemo.com 2. Enter "standard_user" in Username and "secret_sauce" in Password 3. Click Login 4. Click "Add to cart" on Sauce Labs Onesie 5. Click the cart icon, then click Checkout 6. Enter First Name "Test", Last Name "Customer", Zip "12345" and click Continue 7. Double-click Finish very fast | G24: Sauce Labs Onesie | H24: 1. Login page shows the Username field, Password field and Login button. 2. Text is typed. Password shows as dots. 3. Products page opens. URL ends with /inventory.html. Title is "Products". 4. Button changes to "Remove". 5. "Checkout: Your Information" page opens. 6. "Checkout: Overview" page opens. URL ends with /checkout-step-two.html. 7. Only one "Thank you for your order!" page. No error. | I24: P1 | J24: Yes - for what the user sees; the real order count needs an API or database check. | K24: As expected - Only one "Thank you for your order!" page. No error. | L24: Pass | M24: N/A | N24: Only one order should be created - needs backend/order list to fully confirm.
A25: TC20 | B25: Checkout | C25: Usability | D25: Typed values stay after an error | E25: Use a NEW private / incognito browser window (so the cart is empty and no one is logged in). | F25: 1. Open https://www.saucedemo.com 2. Enter "standard_user" in Username and "secret_sauce" in Password 3. Click Login 4. Click "Add to cart" on Sauce Labs Onesie 5. Click the cart icon, then click Checkout 6. Enter Test and Customer, leave Zip empty, click Continue 7. Look at First Name and Last Name | G25: First Name: Test, Last Name: Customer, Zip: empty | H25: 1. Login page shows the Username field, Password field and Login button. 2. Text is typed. Password shows as dots. 3. Products page opens. URL ends with /inventory.html. Title is "Products". 4. Button changes to "Remove". 5. "Checkout: Your Information" page opens. 6. Error: "Error: Postal Code is required". 7. They still show "Test" and "Customer". | I25: P3 | J25: Yes - stable usability check. | K25: As expected - They still show "Test" and "Customer". | L25: Pass | M25: N/A
A26: TC21 | B26: Session | C26: Security | D26: Products page cannot be opened after logout | E26: Use a NEW private / incognito browser window (so the cart is empty and no one is logged in). | F26: 1. Open https://www.saucedemo.com 2. Enter "standard_user" in Username and "secret_sauce" in Password 3. Click Login 4. Click the menu button (☰), then click Logout 5. Type https://www.saucedemo.com/inventory.html in the address bar and press Enter 6. Look at the page | G26: User: standard_user URL: https://www.saucedemo.com/inventory.html | H26: 1. Login page shows the Username field, Password field and Login button. 2. Text is typed. Password shows as dots. 3. Products page opens. URL ends with /inventory.html. Title is "Products". Products are listed. No cart number on the cart icon. 4. Login page is shown. 5. Error shown: "Epic sadface: You can only access '/inventory.html' when you are logged in." 6. Login page is shown. "Products" title is NOT shown. No products are listed. | I26: P1 | J26: Yes - security rule from the brief (open a page by URL after logout). | K26: As expected - error "Epic sadface: You can only access '/inventory.html' when you are logged in." was shown on the login page; no products were shown. | L26: Pass | M26: N/A
A27: TC22 | B27: Session | C27: Security | D27: Open /cart.html without logging in | E27: Use a NEW private / incognito browser window (so the cart is empty and no one is logged in). Do NOT log in. | F27: 1. Check you are not logged in (new private window) 2. Type https://www.saucedemo.com/cart.html in the address bar and press Enter 3. Look at the page | G27: URL: https://www.saucedemo.com/cart.html | H27: 1. No Sauce Demo session is open. 2. Error shown: "Epic sadface: You can only access '/cart.html' when you are logged in." 3. Login page is shown (Username, Password, Login). Cart icon is NOT visible. | I27: P1 | J27: Yes - security rule; fast and stable. | K27: As expected - the login page showed "Epic sadface: You can only access '/cart.html' when you are logged in." and the cart icon was not visible. | L27: Pass | M27: N/A
A28: TC23 | B28: Accessibility | C28: Accessibility | D28: Log in and add a product using only the keyboard | E28: Use a NEW private / incognito browser window (so the cart is empty and no one is logged in). | F28: 1. Open https://www.saucedemo.com 2. Press Tab 3. Type "standard_user" and press Tab 4. Type "secret_sauce" and press Enter 5. Move focus to "Add to cart" on Sauce Labs Backpack and press Enter | G28: standard_user / secret_sauce (no mouse) | H28: 1. Login page is shown. 2. The cursor is in the Username field. 3. The cursor moves to the Password field. 4. Products page opens. 5. Button changes to "Remove". Cart number shows 1. | I28: P2 | J28: Yes - automated as AC03; screen-reader use stays manual. | K28: As expected - login and add to cart worked with the keyboard only. | L28: Pass | M28: N/A | N28: Full accessibility suite (AC01-AC15, WCAG 2.2 A/AA) is listed in README.md. Screen-reader use still needs a manual check.
A29: TC24 | B29: Screen size | C29: Compatibility | D29: Products page works on a mobile and a desktop screen | E29: Use a NEW private / incognito browser window (so the cart is empty and no one is logged in). | F29: 1. Set the browser window to 375 x 667 and log in as standard_user 2. Click "Add to cart" on Sauce Labs Backpack 3. Repeat steps 1-2 at 1366 x 768 | G29: Mobile 375 x 667, desktop 1366 x 768 | H29: 1. No sideways scrolling. Menu button, cart icon and sort dropdown are visible. 2. Cart number shows 1. Still no sideways scrolling. 3. Same result on the desktop size. | I29: P3 | J29: Yes - automated as AC14 (window sizes); real phones stay manual. | K29: As expected - no sideways scrolling and every control worked at both sizes. | L29: Pass | M29: N/A | N29: Window-size check in desktop browsers; real phones still need a manual check.
A30: TC25 | B30: Sorting | C30: Positive | D30: Sort by "Price (low to high)" as problem_user | E30: Use a NEW private / incognito browser window (so the cart is empty and no one is logged in). | F30: 1. Open https://www.saucedemo.com 2. Enter "problem_user" in Username and "secret_sauce" in Password 3. Click Login 4. Select "Price (low to high)" in the sort dropdown 5. Read every price from top to bottom | G30: User: problem_user Password: secret_sauce | H30: 1. Login page shows the Username field, Password field and Login button. 2. Text is typed. Password shows as dots. 3. Products page opens. URL ends with /inventory.html. Title is "Products". Products are listed. No cart number on the cart icon. 4. The list re-orders. 5. Every price is lower than or equal to the next. | I30: P1 | J30: Yes - known bug; the test will show when it is fixed. | K30: Prices stayed in the same order: $29.99, $9.99, $15.99, $49.99, $7.99, $15.99. Sorting did not work. | L30: Fail | M30: BUG-01

Sheet Extended Test Cases
A1: Extended Test Cases - extra regression (73 cases)
A2: Extra functional cases written beyond the brief. Same format; IDs continue from the core suite.
A3: Website: https://www.saucedemo.com | Password for all users: secret_sauce | Results recorded 27-28 Oct 2026 in Chrome, Firefox and Safari (WebKit). Pass = worked in all three browsers. Bug ID "N/A" = no bug found.
A5: ID | B5: Area | C5: Type | D5: Title | E5: Pre-conditions | F5: Steps | G5: Test data | H5: Expected result | I5: Priority (P1-P3) | J5: Automate? (Yes / No) and why | K5: Actual Result | L5: Status | M5: Bug ID | N5: Remarks
A6: TC26 | B6: Login | C6: Positive | D6: Login with the slow user (performance_glitch_user) | E6: Use a NEW private / incognito browser window (so the cart is empty and no one is logged in). | F6: 1. Open https://www.saucedemo.com 2. Enter "performance_glitch_user" and "secret_sauce" 3. Click Login and wait (up to 15 seconds) | G6: Username: performance_glitch_user Password: secret_sauce | H6: 1. Login page is shown. 2. Text is typed. 3. Products page opens. URL ends with /inventory.html. Title is "Products". Products are listed. | I6: P3 | J6: Yes - extended regression; stable login variation. | K6: As expected - Products page opens. URL ends with /inventory.html. Title is "Products". Products are listed. | L6: Pass | M6: N/A
A7: TC27 | B7: Login | C7: Positive | D7: Login using the Enter key | E7: Use a NEW private / incognito browser window (so the cart is empty and no one is logged in). | F7: 1. Open https://www.saucedemo.com 2. Enter "standard_user" and "secret_sauce" 3. Press Enter while the cursor is in the Password field (do not click Login) | G7: standard_user / secret_sauce | H7: 1. Login page shows the Username field, Password field and Login button. 2. Text is typed. 3. Products page opens. URL ends with /inventory.html. | I7: P2 | J7: Yes - extended regression; stable login variation. | K7: As expected - Products page opens. URL ends with /inventory.html. | L7: Pass | M7: N/A
A8: TC28 | B8: Login | C8: Positive | D8: Close the login error message | E8: Use a NEW private / incognito browser window (so the cart is empty and no one is logged in). | F8: 1. Open https://www.saucedemo.com 2. Click Login with both fields empty 3. Click the X button on the error | G8: Both fields empty | H8: 1. Login page shows the Username field, Password field and Login button. 2. Error: "Epic sadface: Username is required" with an X button. 3. Error message disappears. | I8: P3 | J8: Yes - extended regression; stable login variation. | K8: As expected - Error message disappears. | L8: Pass | M8: BUG-05 | N8: Seen on 27-Oct-2026: the fields may keep a red style after closing (BUG-05). Check and note.
A9: TC29 | B9: Login | C9: Positive | D9: Login as problem_user | E9: Use a NEW private / incognito browser window (so the cart is empty and no one is logged in). | F9: 1. Open https://www.saucedemo.com 2. Enter "problem_user" in Username and "secret_sauce" in Password 3. Click Login | G9: problem_user / secret_sauce | H9: 1. Login page shows the Username field, Password field and Login button. 2. Text is typed. Password shows as dots. 3. Products page opens. URL ends with /inventory.html. Title is "Products". | I9: P2 | J9: Yes - extended regression; stable login variation. | K9: As expected - Products page opens. URL ends with /inventory.html. Title is "Products". | L9: Pass | M9: N/A
A10: TC30 | B10: Login | C10: Positive | D10: Login as error_user | E10: Use a NEW private / incognito browser window (so the cart is empty and no one is logged in). | F10: 1. Open https://www.saucedemo.com 2. Enter "error_user" in Username and "secret_sauce" in Password 3. Click Login | G10: error_user / secret_sauce | H10: 1. Login page shows the Username field, Password field and Login button. 2. Text is typed. Password shows as dots. 3. Products page opens. URL ends with /inventory.html. Title is "Products". | I10: P2 | J10: Yes - extended regression; stable login variation. | K10: As expected - Products page opens. URL ends with /inventory.html. Title is "Products". | L10: Pass | M10: N/A
A11: TC31 | B11: Login | C11: Positive | D11: Login as visual_user | E11: Use a NEW private / incognito browser window (so the cart is empty and no one is logged in). | F11: 1. Open https://www.saucedemo.com 2. Enter "visual_user" in Username and "secret_sauce" in Password 3. Click Login | G11: visual_user / secret_sauce | H11: 1. Login page shows the Username field, Password field and Login button. 2. Text is typed. Password shows as dots. 3. Products page opens. URL ends with /inventory.html. Title is "Products". | I11: P2 | J11: Yes - extended regression; stable login variation. | K11: As expected - Products page opens. URL ends with /inventory.html. Title is "Products". | L11: Pass | M11: N/A
A12: TC32 | B12: Login | C12: Positive | D12: Login page content | E12: Use a NEW private / incognito browser window (so the cart is empty and no one is logged in). | F12: 1. Open https://www.saucedemo.com 2. Look at the Username and Password fields 3. Look below the form | G12: - | H12: 1. Login page shows the Username field, Password field and Login button. 2. Placeholders say "Username" and "Password". 3. Accepted usernames are listed: standard_user, locked_out_user, problem_user, performance_glitch_user, error_user, visual_user. Text "Password for all users: secret_sauce" is shown. | I12: P3 | J12: Yes - extended regression; stable login variation. | K12: As expected - Accepted usernames are listed: standard_user, locked_out_user, problem_user, performance_glitch_user, error_user, visual_user. Text "Password for all users: secret_sauce" is shown. | L12: Pass | M12: N/A
A13: TC33 | B13: Login | C13: Negative | D13: Login with a username that does not exist | E13: Use a NEW private / incognito browser window (so the cart is empty and no one is logged in). | F13: 1. Open https://www.saucedemo.com 2. Enter "unknown_user" and "secret_sauce" 3. Click Login 4. Look at the page and the URL | G13: Username: unknown_user Password: secret_sauce | H13: 1. Login page is shown. 2. Text is typed. 3. Error shown: "Epic sadface: Username and password do not match any user in this service" (same message as wrong password). 4. Still on the login page. URL does NOT contain /inventory.html. "Products" title is NOT shown. | I13: P1 | J13: Yes - extended regression; stable login variation. | K13: As expected - the same error "Epic sadface: Username and password do not match any user in this service" was shown and the user stayed on the login page. | L13: Pass | M13: N/A
A14: TC34 | B14: Login | C14: Negative | D14: Login with username empty | E14: Use a NEW private / incognito browser window (so the cart is empty and no one is logged in). | F14: 1. Open https://www.saucedemo.com 2. Leave Username empty, enter "any" in Password 3. Click Login 4. Look at the page and the URL | G14: Username: (empty) Password: any | H14: 1. Login page is shown. 2. Only Password has text. 3. Error shown: "Epic sadface: Username is required" 4. Still on the login page. URL does NOT contain /inventory.html. | I14: P2 | J14: Yes - extended regression; stable login variation. | K14: As expected - error "Epic sadface: Username is required" was shown and the user stayed on the login page. | L14: Pass | M14: N/A
A15: TC35 | B15: Login | C15: Negative | D15: Login with password empty | E15: Use a NEW private / incognito browser window (so the cart is empty and no one is logged in). | F15: 1. Open https://www.saucedemo.com 2. Enter "any" in Username, leave Password empty 3. Click Login 4. Look at the page and the URL | G15: Username: any Password: (empty) | H15: 1. Login page is shown. 2. Only Username has text. 3. Error shown: "Epic sadface: Password is required" 4. Still on the login page. URL does NOT contain /inventory.html. | I15: P2 | J15: Yes - extended regression; stable login variation. | K15: As expected - error "Epic sadface: Password is required" was shown and the user stayed on the login page. | L15: Pass | M15: N/A
A16: TC36 | B16: Login | C16: Negative | D16: Username is case-sensitive | E16: Use a NEW private / incognito browser window (so the cart is empty and no one is logged in). | F16: 1. Open https://www.saucedemo.com 2. Enter "STANDARD_USER" (capital letters) and "secret_sauce", click Login | G16: STANDARD_USER / secret_sauce | H16: 1. Login page shows the Username field, Password field and Login button. 2. Error: "Epic sadface: Username and password do not match any user in this service". Not logged in. | I16: P2 | J16: Yes - extended regression; stable login variation. | K16: As expected - Error: "Epic sadface: Username and password do not match any user in this service". Not logged in. | L16: Pass | M16: N/A | N16: ASSUMPTION: usernames are case-sensitive (confirm with product owner). Seen on 27-Oct-2026: rejected.
A17: TC37 | B17: Login | C17: Negative | D17: Username with spaces before and after | E17: Use a NEW private / incognito browser window (so the cart is empty and no one is logged in). | F17: 1. Open https://www.saucedemo.com 2. Enter " standard_user " (one space before and after) and "secret_sauce", click Login | G17: " standard_user " / secret_sauce | H17: 1. Login page shows the Username field, Password field and Login button. 2. Error: "Epic sadface: Username and password do not match any user in this service". Not logged in. | I17: P3 | J17: Yes - extended regression; stable login variation. | K17: As expected - Error: "Epic sadface: Username and password do not match any user in this service". Not logged in. | L17: Pass | M17: N/A | N17: ASSUMPTION: spaces are not removed (confirm with product owner). Seen on 27-Oct-2026: rejected.
A18: TC38 | B18: Login | C18: Negative | D18: Password is case-sensitive | E18: Use a NEW private / incognito browser window (so the cart is empty and no one is logged in). | F18: 1. Open https://www.saucedemo.com 2. Enter "standard_user" and "SECRET_SAUCE" (capital letters), click Login | G18: standard_user / SECRET_SAUCE | H18: 1. Login page shows the Username field, Password field and Login button. 2. Error: "Epic sadface: Username and password do not match any user in this service". Not logged in. | I18: P2 | J18: Yes - extended regression; stable login variation. | K18: As expected - Error: "Epic sadface: Username and password do not match any user in this service". Not logged in. | L18: Pass | M18: N/A
A19: TC39 | B19: Login | C19: Negative | D19: Script text in username is treated as plain text | E19: Use a NEW private / incognito browser window (so the cart is empty and no one is logged in). | F19: 1. Open https://www.saucedemo.com 2. Enter <script>alert(1)</script> in Username and "secret_sauce" in Password, click Login | G19: Username: <script>alert(1)</script> Password: secret_sauce | H19: 1. Login page shows the Username field, Password field and Login button. 2. No pop-up appears. Error: "Epic sadface: Username and password do not match any user in this service". | I19: P2 | J19: Yes - extended regression; stable login variation. | K19: As expected - No pop-up appears. Error: "Epic sadface: Username and password do not match any user in this service". | L19: Pass | M19: N/A | N19: Safe check only. No real attack is done.
A20: TC40 | B20: Login | C20: Boundary | D20: Very long username and password | E20: Use a NEW private / incognito browser window (so the cart is empty and no one is logged in). | F20: 1. Open https://www.saucedemo.com 2. Paste 1000 letters "a" into Username and into Password 3. Click Login | G20: 1000 x "a" in both fields | H20: 1. Login page shows the Username field, Password field and Login button. 2. Text is accepted; page does not freeze. 3. Error: "Epic sadface: Username and password do not match any user in this service". Page layout is not broken. | I20: P3 | J20: Yes - extended regression; stable login variation. | K20: As expected - Error: "Epic sadface: Username and password do not match any user in this service". Page layout is not broken. | L20: Pass | M20: N/A
A21: TC41 | B21: Products | C21: Positive | D21: Every product shows full details | E21: Use a NEW private / incognito browser window (so the cart is empty and no one is logged in). | F21: 1. Open https://www.saucedemo.com 2. Enter "standard_user" in Username and "secret_sauce" in Password 3. Click Login 4. Look at each product card | G21: standard_user | H21: 1. Login page shows the Username field, Password field and Login button. 2. Text is typed. Password shows as dots. 3. Products page opens. URL ends with /inventory.html. Title is "Products". 4. 6 products. Each card has an image, name, description, price and "Add to cart" button. | I21: P1 | J21: Yes - extended regression; stable page check. | K21: As expected - 6 products. Each card has an image, name, description, price and "Add to cart" button. | L21: Pass | M21: N/A
A22: TC42 | B22: Products | C22: Positive | D22: Product prices format | E22: Use a NEW private / incognito browser window (so the cart is empty and no one is logged in). | F22: 1. Open https://www.saucedemo.com 2. Enter "standard_user" in Username and "secret_sauce" in Password 3. Click Login 4. Read every price | G22: standard_user | H22: 1. Login page shows the Username field, Password field and Login button. 2. Text is typed. Password shows as dots. 3. Products page opens. URL ends with /inventory.html. Title is "Products". 4. Every price starts with $ and has 2 decimals: $29.99, $9.99, $15.99, $49.99, $7.99, $15.99. | I22: P2 | J22: Yes - extended regression; stable page check. | K22: As expected - Every price starts with $ and has 2 decimals: $29.99, $9.99, $15.99, $49.99, $7.99, $15.99. | L22: Pass | M22: N/A
A23: TC43 | B23: Products | C23: Positive | D23: Product name opens the product detail page | E23: Use a NEW private / incognito browser window (so the cart is empty and no one is logged in). | F23: 1. Open https://www.saucedemo.com 2. Enter "standard_user" in Username and "secret_sauce" in Password 3. Click Login 4. Click the name "Sauce Labs Backpack" 5. Check the details | G23: Sauce Labs Backpack | H23: 1. Login page shows the Username field, Password field and Login button. 2. Text is typed. Password shows as dots. 3. Products page opens. URL ends with /inventory.html. Title is "Products". 4. Product page opens. URL contains /inventory-item.html?id=4. 5. Name "Sauce Labs Backpack", price $29.99 and the same description as the Products page. "Back to products" button is shown. | I23: P2 | J23: Yes - extended regression; stable page check. | K23: As expected - Name "Sauce Labs Backpack", price $29.99 and the same description as the Products page. "Back to products" button is shown. | L23: Pass | M23: N/A
A24: TC44 | B24: Products | C24: Positive | D24: Product image opens the product detail page | E24: Use a NEW private / incognito browser window (so the cart is empty and no one is logged in). | F24: 1. Open https://www.saucedemo.com 2. Enter "standard_user" in Username and "secret_sauce" in Password 3. Click Login 4. Click the image of "Sauce Labs Bike Light" | G24: Sauce Labs Bike Light | H24: 1. Login page shows the Username field, Password field and Login button. 2. Text is typed. Password shows as dots. 3. Products page opens. URL ends with /inventory.html. Title is "Products". 4. Product page for Sauce Labs Bike Light opens, price $9.99. | I24: P2 | J24: Yes - extended regression; stable page check. | K24: As expected - Product page for Sauce Labs Bike Light opens, price $9.99. | L24: Pass | M24: N/A
A25: TC45 | B25: Products | C25: Positive | D25: Default sort after login | E25: Use a NEW private / incognito browser window (so the cart is empty and no one is logged in). | F25: 1. Open https://www.saucedemo.com 2. Enter "standard_user" in Username and "secret_sauce" in Password 3. Click Login 4. Look at the sort dropdown and the list | G25: standard_user | H25: 1. Login page shows the Username field, Password field and Login button. 2. Text is typed. Password shows as dots. 3. Products page opens. URL ends with /inventory.html. Title is "Products". 4. Dropdown shows "Name (A to Z)". Names are in A to Z order. | I25: P2 | J25: Yes - extended regression; stable page check. | K25: As expected - Dropdown shows "Name (A to Z)". Names are in A to Z order. | L25: Pass | M25: N/A
A26: TC46 | B26: Products | C26: Positive | D26: Footer social links | E26: Use a NEW private / incognito browser window (so the cart is empty and no one is logged in). | F26: 1. Open https://www.saucedemo.com 2. Enter "standard_user" in Username and "secret_sauce" in Password 3. Click Login 4. Scroll to the footer 5. Click each icon | G26: X, Facebook, LinkedIn | H26: 1. Login page shows the Username field, Password field and Login button. 2. Text is typed. Password shows as dots. 3. Products page opens. URL ends with /inventory.html. Title is "Products". 4. X, Facebook and LinkedIn icons are shown. 5. Each opens in a new tab: x.com/saucelabs, facebook.com/saucelabs, linkedin.com/company/sauce-labs. | I26: P3 | J26: Yes - extended regression; stable page check. | K26: As expected - the X, Facebook and LinkedIn links point to the Sauce Labs pages and are set to open in a new tab. The external sites were not opened. | L26: Pass | M26: N/A | N26: Do not test the external sites, only that the right page opens.
A27: TC47 | B27: Sorting | C27: Positive | D27: Added products keep "Remove" after sorting | E27: Use a NEW private / incognito browser window (so the cart is empty and no one is logged in). | F27: 1. Open https://www.saucedemo.com 2. Enter "standard_user" in Username and "secret_sauce" in Password 3. Click Login 4. Click "Add to cart" on Backpack and on Onesie 5. Select "Price (high to low)" 6. Find Backpack and Onesie in the new order | G27: Sauce Labs Backpack, Sauce Labs Onesie | H27: 1. Login page shows the Username field, Password field and Login button. 2. Text is typed. Password shows as dots. 3. Products page opens. URL ends with /inventory.html. Title is "Products". 4. Both buttons change to "Remove". Cart number shows 2. 5. List re-orders. 6. Both still show "Remove". All other products show "Add to cart". Cart number still 2. | I27: P2 | J27: Yes - extended regression; whole-list check. | K27: As expected - Both still show "Remove". All other products show "Add to cart". Cart number still 2. | L27: Pass | M27: N/A
A28: TC48 | B28: Sorting | C28: Positive | D28: Change sort many times | E28: Use a NEW private / incognito browser window (so the cart is empty and no one is logged in). | F28: 1. Open https://www.saucedemo.com 2. Enter "standard_user" in Username and "secret_sauce" in Password 3. Click Login 4. Select Name (Z to A), then Price (low to high), then Price (high to low), then Name (A to Z) 5. After each selection, read the full list | G28: All 4 sort options | H28: 1. Login page shows the Username field, Password field and Login button. 2. Text is typed. Password shows as dots. 3. Products page opens. URL ends with /inventory.html. Title is "Products". 4. List re-orders each time. 5. Each time the whole list is in the chosen order. Always 6 products. | I28: P3 | J28: Yes - extended regression; whole-list check. | K28: As expected - Each time the whole list is in the chosen order. Always 6 products. | L28: Pass | M28: N/A
A29: TC49 | B29: Product Detail | C29: Positive | D29: Add to cart from the product page | E29: Use a NEW private / incognito browser window (so the cart is empty and no one is logged in). | F29: 1. Open https://www.saucedemo.com 2. Enter "standard_user" in Username and "secret_sauce" in Password 3. Click Login 4. Click the name "Sauce Labs Backpack" 5. Click "Add to cart" | G29: Sauce Labs Backpack | H29: 1. Login page shows the Username field, Password field and Login button. 2. Text is typed. Password shows as dots. 3. Products page opens. URL ends with /inventory.html. Title is "Products". 4. Product page opens. 5. Button changes to "Remove". Cart number shows 1. | I29: P1 | J29: Yes - extended regression; stable page check. | K29: As expected - Button changes to "Remove". Cart number shows 1. | L29: Pass | M29: N/A
A30: TC50 | B30: Product Detail | C30: Positive | D30: Remove from the product page | E30: Use a NEW private / incognito browser window (so the cart is empty and no one is logged in). | F30: 1. Open https://www.saucedemo.com 2. Enter "standard_user" in Username and "secret_sauce" in Password 3. Click Login 4. Open "Sauce Labs Backpack" and click "Add to cart" 5. Click "Remove" | G30: Sauce Labs Backpack | H30: 1. Login page shows the Username field, Password field and Login button. 2. Text is typed. Password shows as dots. 3. Products page opens. URL ends with /inventory.html. Title is "Products". 4. Cart number shows 1. 5. Button changes to "Add to cart". Cart number is gone. | I30: P2 | J30: Yes - extended regression; stable page check. | K30: As expected - Button changes to "Add to cart". Cart number is gone. | L30: Pass | M30: N/A
A31: TC51 | B31: Product Detail | C31: Positive | D31: "Back to products" keeps the cart | E31: Use a NEW private / incognito browser window (so the cart is empty and no one is logged in). | F31: 1. Open https://www.saucedemo.com 2. Enter "standard_user" in Username and "secret_sauce" in Password 3. Click Login 4. Open "Sauce Labs Backpack" and click "Add to cart" 5. Click "Back to products" | G31: Sauce Labs Backpack | H31: 1. Login page shows the Username field, Password field and Login button. 2. Text is typed. Password shows as dots. 3. Products page opens. URL ends with /inventory.html. Title is "Products". 4. Cart number shows 1. 5. Products page opens. Cart number still 1. Backpack shows "Remove". | I31: P2 | J31: Yes - extended regression; stable page check. | K31: As expected - Products page opens. Cart number still 1. Backpack shows "Remove". | L31: Pass | M31: N/A
A32: TC52 | B32: Product Detail | C32: Negative | D32: Unknown product id | E32: Use a NEW private / incognito browser window (so the cart is empty and no one is logged in). | F32: 1. Open https://www.saucedemo.com 2. Enter "standard_user" in Username and "secret_sauce" in Password 3. Click Login 4. Type https://www.saucedemo.com/inventory-item.html?id=99 in the address bar 5. Click "Back to products" | G32: https://www.saucedemo.com/inventory-item.html?id=99 | H32: 1. Login page shows the Username field, Password field and Login button. 2. Text is typed. Password shows as dots. 3. Products page opens. URL ends with /inventory.html. Title is "Products". 4. Page shows "ITEM NOT FOUND". No crash. 5. Products page opens. | I32: P3 | J32: Yes - extended regression; stable page check. | K32: As expected - "ITEM NOT FOUND" was shown and "Back to products" opened the Products page. | L32: Pass | M32: N/A
A33: TC53 | B33: Product Detail | C33: Negative | D33: Product id is not a number | E33: Use a NEW private / incognito browser window (so the cart is empty and no one is logged in). | F33: 1. Open https://www.saucedemo.com 2. Enter "standard_user" in Username and "secret_sauce" in Password 3. Click Login 4. Type https://www.saucedemo.com/inventory-item.html?id=abc in the address bar 5. Click "Back to products" | G33: https://www.saucedemo.com/inventory-item.html?id=abc | H33: 1. Login page shows the Username field, Password field and Login button. 2. Text is typed. Password shows as dots. 3. Products page opens. URL ends with /inventory.html. Title is "Products". 4. Page shows "ITEM NOT FOUND". No crash, no blank page. 5. Products page opens. | I33: P3 | J33: Yes - extended regression; stable page check. | K33: As expected - "ITEM NOT FOUND" was shown and "Back to products" opened the Products page. | L33: Pass | M33: N/A
A34: TC54 | B34: Cart | C34: Positive | D34: Cart item details | E34: Use a NEW private / incognito browser window (so the cart is empty and no one is logged in). | F34: 1. Open https://www.saucedemo.com 2. Enter "standard_user" in Username and "secret_sauce" in Password 3. Click Login 4. Add "Sauce Labs Bolt T-Shirt", open the cart 5. Look at the cart line | G34: Sauce Labs Bolt T-Shirt | H34: 1. Login page shows the Username field, Password field and Login button. 2. Text is typed. Password shows as dots. 3. Products page opens. URL ends with /inventory.html. Title is "Products". 4. "Your Cart" page opens. 5. QTY 1, name "Sauce Labs Bolt T-Shirt", description, price $15.99, "Remove" button. | I34: P1 | J34: Yes - extended regression; cart state check. | K34: As expected - QTY 1, name "Sauce Labs Bolt T-Shirt", description, price $15.99, "Remove" button. | L34: Pass | M34: N/A
A35: TC55 | B35: Cart | C35: Positive | D35: Cart stays the same when moving between pages | E35: Use a NEW private / incognito browser window (so the cart is empty and no one is logged in). | F35: 1. Open https://www.saucedemo.com 2. Enter "standard_user" in Username and "secret_sauce" in Password 3. Click Login 4. Add Backpack and Bike Light 5. Open Backpack product page, go back, open the cart, click Continue Shopping | G35: 2 products | H35: 1. Login page shows the Username field, Password field and Login button. 2. Text is typed. Password shows as dots. 3. Products page opens. URL ends with /inventory.html. Title is "Products". 4. Cart number shows 2. 5. Cart number is 2 on every page. Cart lists Backpack and Bike Light. | I35: P1 | J35: Yes - extended regression; cart state check. | K35: As expected - Cart number is 2 on every page. Cart lists Backpack and Bike Light. | L35: Pass | M35: N/A
